Workbook

Sheet Gestión de abastecimiento
A1: Dimension 1
B3: Planificación | H3: Transparencia | N3: Cumplimiento normativo | T3: Total | U3: Valoración
B4: PRG.1 | C4: PRG.2 | D4: PRG.3 | E4: PRG.4 | F4: PRG.5 | G4: PRG.6 | H4: PRG.7 | I4: PRG.8 | J4: PRG.9 | K4: PRG.10 | L4: PRG.11 | M4: PRG.12 | N4: PRG.13 | O4: PRG.14 | P4: PRG.15 | Q4: PRG.16 | R4: PRG.17 | S4: PRG.18
A5: Beneficiaros 1 | B5: 3 | C5: 4 | D5: 4 | E5: 3 | F5: 4 | G5: 5 | H5: 3 | I5: 4 | J5: 5 | K5: 4 | L5: 4 | M5: 3 | N5: 5 | O5: 3 | P5: 5 | Q5: 4 | R5: 5 | S5: 5 | T5: 73
A6: Beneficiaros 2 | B6: 2 | C6: 3 | D6: 2 | E6: 3 | F6: 3 | G6: 3 | H6: 2 | I6: 3 | J6: 2 | K6: 3 | L6: 2 | M6: 3 | N6: 3 | O6: 3 | P6: 3 | Q6: 2 | R6: 2 | S6: 3 | T6: 47
A7: Beneficiaros 3 | B7: 4 | C7: 4 | D7: 2 | E7: 3 | F7: 4 | G7: 4 | H7: 3 | I7: 3 | J7: 4 | K7: 2 | L7: 4 | M7: 4 | N7: 3 | O7: 4 | P7: 3 | Q7: 3 | R7: 3 | S7: 3 | T7: 60
A8: Beneficiaros 4 | B8: 2 | C8: 2 | D8: 3 | E8: 2 | F8: 3 | G8: 2 | H8: 2 | I8: 2 | J8: 3 | K8: 3 | L8: 3 | M8: 3 | N8: 2 | O8: 3 | P8: 2 | Q8: 3 | R8: 3 | S8: 2 | T8: 45
A9: Beneficiaros 5 | B9: 3 | C9: 2 | D9: 3 | E9: 3 | F9: 2 | G9: 3 | H9: 3 | I9: 3 | J9: 3 | K9: 2 | L9: 2 | M9: 3 | N9: 2 | O9: 3 | P9: 3 | Q9: 2 | R9: 2 | S9: 2 | T9: 46
A10: Beneficiaros 6 | B10: 2 | C10: 3 | D10: 3 | E10: 4 | F10: 2 | G10: 3 | H10: 2 | I10: 3 | J10: 4 | K10: 2 | L10: 3 | M10: 4 | N10: 2 | O10: 3 | P10: 3 | Q10: 3 | R10: 3 | S10: 3 | T10: 52
A11: Beneficiaros 7 | B11: 3 | C11: 4 | D11: 4 | E11: 3 | F11: 2 | G11: 2 | H11: 3 | I11: 3 | J11: 4 | K11: 3 | L11: 3 | M11: 4 | N11: 3 | O11: 4 | P11: 4 | Q11: 2 | R11: 4 | S11: 4 | T11: 59
A12: Beneficiaros 8 | B12: 2 | C12: 1 | D12: 2 | E12: 1 | F12: 2 | G12: 2 | H12: 1 | I12: 2 | J12: 1 | K12: 2 | L12: 1 | M12: 2 | N12: 2 | O12: 1 | P12: 1 | Q12: 1 | R12: 1 | S12: 1 | T12: 26
A13: Beneficiaros 9 | B13: 1 | C13: 1 | D13: 1 | E13: 1 | F13: 2 | G13: 1 | H13: 2 | I13: 2 | J13: 2 | K13: 1 | L13: 1 | M13: 1 | N13: 1 | O13: 2 | P13: 2 | Q13: 1 | R13: 2 | S13: 2 | T13: 26
A14: Beneficiaros 10 | B14: 2 | C14: 1 | D14: 2 | E14: 2 | F14: 1 | G14: 1 | H14: 2 | I14: 2 | J14: 1 | K14: 1 | L14: 2 | M14: 2 | N14: 1 | O14: 2 | P14: 1 | Q14: 1 | R14: 1 | S14: 1 | T14: 26
A15: Beneficiaros 11 | B15: 1 | C15: 1 | D15: 1 | E15: 1 | F15: 1 | G15: 1 | H15: 1 | I15: 1 | J15: 1 | K15: 1 | L15: 1 | M15: 1 | N15: 1 | O15: 1 | P15: 1 | Q15: 1 | R15: 1 | S15: 1 | T15: 18
A16: Beneficiaros 12 | B16: 2 | C16: 3 | D16: 2 | E16: 3 | F16: 3 | G16: 2 | H16: 2 | I16: 1 | J16: 3 | K16: 2 | L16: 2 | M16: 2 | N16: 2 | O16: 2 | P16: 2 | Q16: 3 | R16: 2 | S16: 3 | T16: 41
... A293: Beneficiaros 289 | B293: 2 | C293: 2 | D293: 2 | E293: 1 | F293: 1 | G293: 2 | H293: 1 | I293: 2 | J293: 2 | K293: 1 | L293: 2 | M293: 2 | N293: 2 | O293: 1 | P293: 1 | Q293: 2 | R293: 1 | S293: 1 | T293: 28
A294: TOTAL | B294: =SUM(B5:B293) -> 0 | C294: =SUM(C5:C293) -> 0 | D294: =SUM(D5:D293) -> 0 | E294: =SUM(E5:E293) -> 0 | F294: =SUM(F5:F293) -> 0 | G294: =SUM(G5:G293) -> 0 | H294: =SUM(H5:H293) -> 0 | I294: =SUM(I5:I293) -> 0 | ... T294: =SUM(T5:T293) -> 0
A295: MODA | B295: =MODE(B5:B293) -> 0 | C295: =MODE(C5:C293) -> 0 | D295: =MODE(D5:D293) -> 0 | E295: =MODE(E5:E293) -> 0 | F295: =MODE(F5:F293) -> 0 | G295: =MODE(G5:G293) -> 0 | H295: =MODE(H5:H293) -> 0 | I295: =MODE(I5:I293) -> 0 | ... T295: =MODE(T5:T293) -> 0
A296: MEDIA | B296: =(B294/289) -> 0 | C296: =(C294/289) -> 0 | D296: =(D294/289) -> 0 | E296: =(E294/289) -> 0 | F296: =(F294/289) -> 0 | G296: =(G294/289) -> 0 | H296: =(H294/289) -> 0 | I296: =(I294/289) -> 0 | ... T296: =(T294/289) -> 0
A297: MEDIANA | B297: =MEDIAN(B5:B293) -> 0 | C297: =MEDIAN(C5:C293) -> 0 | D297: =MEDIAN(D5:D293) -> 0 | E297: =MEDIAN(E5:E293) -> 0 | F297: =MEDIAN(F5:F293) -> 0 | G297: =MEDIAN(G5:G293) -> 0 | H297: =MEDIAN(H5:H293) -> 0 | I297: =MEDIAN(I5:I293) -> 0 | ... T297: =MEDIAN(T5:T293) -> 0
A298: Desv.Est | B298: =ROUND(STDEV(B5:B293),2) -> 0 | C298: =ROUND(STDEV(C5:C293),2) -> 0 | D298: =ROUND(STDEV(D5:D293),2) -> 0 | E298: =ROUND(STDEV(E5:E293),2) -> 0 | F298: =ROUND(STDEV(F5:F293),2) -> 0 | G298: =ROUND(STDEV(G5:G293),2) -> 0 | H298: =ROUND(STDEV(H5:H293),2) -> 0 | I298: =ROUND(STDEV(I5:I293),2) -> 0 | ... T298: =ROUND(STDEV(T5:T293),2) -> 0
A299: Coef. Varia. | B299: =(B298/B296) -> 0 | C299: =(C298/C296) -> 0 | D299: =(D298/D296) -> 0 | E299: =(E298/E296) -> 0 | F299: =(F298/F296) -> 0 | G299: =(G298/G296) -> 0 | H299: =(H298/H296) -> 0 | I299: =(I298/I296) -> 0 | ... T299: =(T298/T296) -> 0
A300: Totalmente en desacuerdo | B300: =COUNTIF($B$5:$B$293,$A1289) -> 0 | C300: =COUNTIF($C$5:$C$293,$A1289) -> 0 | D300: =COUNTIF($D$5:$D$293,$A1289) -> 0 | E300: =COUNTIF($E$5:$E$293,$A1289) -> 0 | F300: =COUNTIF($F$5:$F$293,$A1289) -> 0 | G300: =COUNTIF($G$5:$G$293,$A1289) -> 0 | H300: =COUNTIF($H$5:$H$293,$A1289) -> 0 | I300: =COUNTIF($I$5:$I$293,$A1289) -> 0 | J300: =COUNTIF($J$5:$J$293,$A1289) -> 0 | K300: =COUNTIF($K$5:$K$293,$A1289) -> 0 | L300: =COUNTIF($L$5:$L$293,$A1289) -> 0 | M300: =COUNTIF($M$5:$M$293,$A1289) -> 0 | N300: =COUNTIF($N$5:$N$293,$A1289) -> 0 | O300: =COUNTIF($O$5:$O$293,$A1289) -> 0 | P300: =COUNTIF($P$5:$P$293,$A1289) -> 0 | Q300: =COUNTIF($Q$5:$Q$293,$A1289) -> 0 | R300: =COUNTIF($R$5:$R$293,$A1289) -> 0 | S300: =COUNTIF($S$5:$S$293,$A1289) -> 0
A301: En desacuerdo | B301: =COUNTIF($B$5:$B$293,$A1290) -> 0 | C301: =COUNTIF($C$5:$C$293,$A1290) -> 0 | D301: =COUNTIF($D$5:$D$293,$A1290) -> 0 | E301: =COUNTIF($E$5:$E$293,$A1290) -> 0 | F301: =COUNTIF($F$5:$F$293,$A1290) -> 0 | G301: =COUNTIF($G$5:$G$293,$A1290) -> 0 | H301: =COUNTIF($H$5:$H$293,$A1290) -> 0 | I301: =COUNTIF($I$5:$I$293,$A1290) -> 0 | J301: =COUNTIF($J$5:$J$293,$A1290) -> 0 | K301: =COUNTIF($K$5:$K$293,$A1290) -> 0 | L301: =COUNTIF($L$5:$L$293,$A1290) -> 0 | M301: =COUNTIF($M$5:$M$293,$A1290) -> 0 | N301: =COUNTIF($N$5:$N$293,$A1290) -> 0 | O301: =COUNTIF($O$5:$O$293,$A1290) -> 0 | P301: =COUNTIF($P$5:$P$293,$A1290) -> 0 | Q301: =COUNTIF($Q$5:$Q$293,$A1290) -> 0 | R301: =COUNTIF($R$5:$R$293,$A1290) -> 0 | S301: =COUNTIF($S$5:$S$293,$A1290) -> 0
A302: Ni de acuerdo ni en desacuerdo | B302: =COUNTIF($B$5:$B$293,$A1291) -> 0 | C302: =COUNTIF($C$5:$C$293,$A1291) -> 0 | D302: =COUNTIF($D$5:$D$293,$A1291) -> 0 | E302: =COUNTIF($E$5:$E$293,$A1291) -> 0 | F302: =COUNTIF($F$5:$F$293,$A1291) -> 0 | G302: =COUNTIF($G$5:$G$293,$A1291) -> 0 | H302: =COUNTIF($H$5:$H$293,$A1291) -> 0 | I302: =COUNTIF($I$5:$I$293,$A1291) -> 0 | J302: =COUNTIF($J$5:$J$293,$A1291) -> 0 | K302: =COUNTIF($K$5:$K$293,$A1291) -> 0 | L302: =COUNTIF($L$5:$L$293,$A1291) -> 0 | M302: =COUNTIF($M$5:$M$293,$A1291) -> 0 | N302: =COUNTIF($N$5:$N$293,$A1291) -> 0 | O302: =COUNTIF($O$5:$O$293,$A1291) -> 0 | P302: =COUNTIF($P$5:$P$293,$A1291) -> 0 | Q302: =COUNTIF($Q$5:$Q$293,$A1291) -> 0 | R302: =COUNTIF($R$5:$R$293,$A1291) -> 0 | S302: =COUNTIF($S$5:$S$293,$A1291) -> 0
A303: De acuerdo | B303: =COUNTIF($B$5:$B$293,$A1292) -> 0 | C303: =COUNTIF($C$5:$C$293,$A1292) -> 0 | D303: =COUNTIF($D$5:$D$293,$A1292) -> 0 | E303: =COUNTIF($E$5:$E$293,$A1292) -> 0 | F303: =COUNTIF($F$5:$F$293,$A1292) -> 0 | G303: =COUNTIF($G$5:$G$293,$A1292) -> 0 | H303: =COUNTIF($H$5:$H$293,$A1292) -> 0 | I303: =COUNTIF($I$5:$I$293,$A1292) -> 0 | J303: =COUNTIF($J$5:$J$293,$A1292) -> 0 | K303: =COUNTIF($K$5:$K$293,$A1292) -> 0 | L303: =COUNTIF($L$5:$L$293,$A1292) -> 0 | M303: =COUNTIF($M$5:$M$293,$A1292) -> 0 | N303: =COUNTIF($N$5:$N$293,$A1292) -> 0 | O303: =COUNTIF($O$5:$O$293,$A1292) -> 0 | P303: =COUNTIF($P$5:$P$293,$A1292) -> 0 | Q303: =COUNTIF($Q$5:$Q$293,$A1292) -> 0 | R303: =COUNTIF($R$5:$R$293,$A1292) -> 0 | S303: =COUNTIF($S$5:$S$293,$A1292) -> 0
A304: Totalmente de acuerdo | B304: =COUNTIF($B$5:$B$293,$A1293) -> 0 | C304: =COUNTIF($C$5:$C$293,$A1293) -> 0 | D304: =COUNTIF($D$5:$D$293,$A1293) -> 0 | E304: =COUNTIF($E$5:$E$293,$A1293) -> 0 | F304: =COUNTIF($F$5:$F$293,$A1293) -> 0 | G304: =COUNTIF($G$5:$G$293,$A1293) -> 0 | H304: =COUNTIF($H$5:$H$293,$A1293) -> 0 | I304: =COUNTIF($I$5:$I$293,$A1293) -> 0 | J304: =COUNTIF($J$5:$J$293,$A1293) -> 0 | K304: =COUNTIF($K$5:$K$293,$A1293) -> 0 | L304: =COUNTIF($L$5:$L$293,$A1293) -> 0 | M304: =COUNTIF($M$5:$M$293,$A1293) -> 0 | N304: =COUNTIF($N$5:$N$293,$A1293) -> 0 | O304: =COUNTIF($O$5:$O$293,$A1293) -> 0 | P304: =COUNTIF($P$5:$P$293,$A1293) -> 0 | Q304: =COUNTIF($Q$5:$Q$293,$A1293) -> 0 | R304: =COUNTIF($R$5:$R$293,$A1293) -> 0 | S304: =COUNTIF($S$5:$S$293,$A1293) -> 0
A305: Total | B305: =SUM($B300:$B304) -> 0 | C305: =SUM($C300:$C304) -> 0 | D305: =SUM($D300:$D304) -> 0 | E305: =SUM($E300:$E304) -> 0 | F305: =SUM($F300:$F304) -> 0 | G305: =SUM($G300:$G304) -> 0 | H305: =SUM($H300:$H304) -> 0 | I305: =SUM($I300:$I304) -> 0 | J305: =SUM($J300:$J304) -> 0 | K305: =SUM($K300:$K304) -> 0 | L305: =SUM($L300:$L304) -> 0 | M305: =SUM($M300:$M304) -> 0 | N305: =SUM($N300:$N304) -> 0 | O305: =SUM($O300:$O304) -> 0 | P305: =SUM($P300:$P304) -> 0 | Q305: =SUM($Q300:$Q304) -> 0 | R305: =SUM($R300:$R304) -> 0 | S305: =SUM($S300:$S304) -> 0
A306: Totalmente en desacuerdo% | B306: =($B300/$B305) -> 0 | C306: =($C300/$C305) -> 0 | D306: =($D300/$D305) -> 0 | E306: =($E300/$E305) -> 0 | F306: =($F300/$F305) -> 0 | G306: =($G300/$G305) -> 0 | H306: =($H300/$H305) -> 0 | I306: =($I300/$I305) -> 0 | J306: =($J300/$J305) -> 0 | K306: =($K300/$K305) -> 0 | L306: =($L300/$L305) -> 0 | M306: =($M300/$M305) -> 0 | N306: =($N300/$N305) -> 0 | O306: =($O300/$O305) -> 0 | P306: =($P300/$P305) -> 0 | Q306: =($Q300/$Q305) -> 0 | R306: =($R300/$R305) -> 0 | S306: =($S300/$S305) -> 0
A307: En desacuerdo% | B307: =($B301/$B305) -> 0 | C307: =($C301/$C305) -> 0 | D307: =($D301/$D305) -> 0 | E307: =($E301/$E305) -> 0 | F307: =($F301/$F305) -> 0 | G307: =($G301/$G305) -> 0 | H307: =($H301/$H305) -> 0 | I307: =($I301/$I305) -> 0 | J307: =($J301/$J305) -> 0 | K307: =($K301/$K305) -> 0 | L307: =($L301/$L305) -> 0 | M307: =($M301/$M305) -> 0 | N307: =($N301/$N305) -> 0 | O307: =($O301/$O305) -> 0 | P307: =($P301/$P305) -> 0 | Q307: =($Q301/$Q305) -> 0 | R307: =($R301/$R305) -> 0 | S307: =($S301/$S305) -> 0
A308: Ni de acuerdo ni en desacuerdo% | B308: =($B302/$B305) -> 0 | C308: =($C302/$C305) -> 0 | D308: =($D302/$D305) -> 0 | E308: =($E302/$E305) -> 0 | F308: =($F302/$F305) -> 0 | G308: =($G302/$G305) -> 0 | H308: =($H302/$H305) -> 0 | I308: =($I302/$I305) -> 0 | J308: =($J302/$J305) -> 0 | K308: =($K302/$K305) -> 0 | L308: =($L302/$L305) -> 0 | M308: =($M302/$M305) -> 0 | N308: =($N302/$N305) -> 0 | O308: =($O302/$O305) -> 0 | P308: =($P302/$P305) -> 0 | Q308: =($Q302/$Q305) -> 0 | R308: =($R302/$R305) -> 0 | S308: =($S302/$S305) -> 0
A309: De acuerdo% | B309: =($B303/$B305) -> 0 | C309: =($C303/$C305) -> 0 | D309: =($D303/$D305) -> 0 | E309: =($E303/$E305) -> 0 | F309: =($F303/$F305) -> 0 | G309: =($G303/$G305) -> 0 | H309: =($H303/$H305) -> 0 | I309: =($I303/$I305) -> 0 | J309: =($J303/$J305) -> 0 | K309: =($K303/$K305) -> 0 | L309: =($L303/$L305) -> 0 | M309: =($M303/$M305) -> 0 | N309: =($N303/$N305) -> 0 | O309: =($O303/$O305) -> 0 | P309: =($P303/$P305) -> 0 | Q309: =($Q303/$Q305) -> 0 | R309: =($R303/$R305) -> 0 | S309: =($S303/$S305) -> 0
A310: Totalmente de acuerdo% | B310: =($B304/$B305) -> 0 | C310: =($C304/$C305) -> 0 | D310: =($D304/$D305) -> 0 | E310: =($E304/$E305) -> 0 | F310: =($F304/$F305) -> 0 | G310: =($G304/$G305) -> 0 | H310: =($H304/$H305) -> 0 | I310: =($I304/$I305) -> 0 | J310: =($J304/$J305) -> 0 | K310: =($K304/$K305) -> 0 | L310: =($L304/$L305) -> 0 | M310: =($M304/$M305) -> 0 | N310: =($N304/$N305) -> 0 | O310: =($O304/$O305) -> 0 | P310: =($P304/$P305) -> 0 | Q310: =($Q304/$Q305) -> 0 | R310: =($R304/$R305) -> 0 | S310: =($S304/$S305) -> 0
A311: Total % | B311: =SUM($B306:$B310) -> 0 | C311: =SUM($C306:$C310) -> 0 | D311: =SUM($D306:$D310) -> 0 | E311: =SUM($E306:$E310) -> 0 | F311: =SUM($F306:$F310) -> 0 | G311: =SUM($G306:$G310) -> 0 | H311: =SUM($H306:$H310) -> 0 | I311: =SUM($I306:$I310) -> 0 | J311: =SUM($J306:$J310) -> 0 | K311: =SUM($K306:$K310) -> 0 | L311: =SUM($L306:$L310) -> 0 | M311: =SUM($M306:$M310) -> 0 | N311: =SUM($N306:$N310) -> 0 | O311: =SUM($O306:$O310) -> 0 | P311: =SUM($P306:$P310) -> 0 | Q311: =SUM($Q306:$Q310) -> 0 | R311: =SUM($R306:$R310) -> 0 | S311: =SUM($S306:$S310) -> 0
A1289: 1
A1290: 2
A1291: 3
A1292: 4
A1293: 5
B1294: =SUM($B1289:$B1293) -> 0 | C1294: =SUM($C1289:$C1293) -> 0 | D1294: =SUM($D1289:$D1293) -> 0 | E1294: =SUM($E1289:$E1293) -> 0 | F1294: =SUM($F1289:$F1293) -> 0 | G1294: =SUM($G1289:$G1293) -> 0 | H1294: =SUM($H1289:$H1293) -> 0 | I1294: =SUM($I1289:$I1293) -> 0 | J1294: =SUM($J1289:$J1293) -> 0 | K1294: =SUM($K1289:$K1293) -> 0 | L1294: =SUM($L1289:$L1293) -> 0 | M1294: =SUM($M1289:$M1293) -> 0 | N1294: =SUM($N1289:$N1293) -> 0 | O1294: =SUM($O1289:$O1293) -> 0 | P1294: =SUM($P1289:$P1293) -> 0 | Q1294: =SUM($Q1289:$Q1293) -> 0 | R1294: =SUM($R1289:$R1293) -> 0 | S1294: =SUM($S1289:$S1293) -> 0
...

Sheet Por Valoracion (3) Dimension
A1: Dimension 1
A2: Nº de Personas | B2: Planificación | D2: Transparencia | F2: Cumplimiento normativo | H2: Gestión de abastecimiento
B3: Suma Total | C3: Valoración | D3: Suma Total | E3: Valoración | F3: Suma Total | G3: Valoración | H3: Suma Total | I3: Valoración
A4: Beneficiaros 1 | B4: =SUM('Gestión de abastecimiento'!B5:G5) -> 0 | C4: =IF(B4<=$Q$19,"Bajo",IF(B4<=$Q$20,"Medio ",IF(B4<=$Q$21,"Alto",0))) -> 0 | D4: =SUM('Gestión de abastecimiento'!H5:M5) -> 0 | E4: =IF(D4<=$AC$19,"Bajo",IF(D4<=$AC$20,"Medio ",IF(D4<=$AC$21,"Alto",0))) -> 0 | F4: =SUM('Gestión de abastecimiento'!N5:S5) -> 0 | G4: =IF(F4<=$AO$19,"Bajo",IF(F4<=$AO$20,"Medio ",IF(F4<=$AO$21,"Alto",0))) -> 0 | H4: =SUM(B4:F4) -> 0 | I4: =IF(H4<=$BA$19,"Bajo",IF(H4<=$BA$20,"Medio ",IF(H4<=$BA$21,"Alto",0))) -> 0 | M4: Variable | N4: Gestión de abastecimiento | Y4: Variable | Z4: Gestión de abastecimiento | AK4: Variable | AL4: Gestión de abastecimiento | AW4: Variable | AX4: Gestión de abastecimiento
A5: Beneficiaros 2 | B5: =SUM('Gestión de abastecimiento'!B6:G6) -> 0 | C5: =IF(B5<=$Q$19,"Bajo",IF(B5<=$Q$20,"Medio ",IF(B5<=$Q$21,"Alto",0))) -> 0 | D5: =SUM('Gestión de abastecimiento'!H6:M6) -> 0 | E5: =IF(D5<=$AC$19,"Bajo",IF(D5<=$AC$20,"Medio ",IF(D5<=$AC$21,"Alto",0))) -> 0 | F5: =SUM('Gestión de abastecimiento'!N6:S6) -> 0 | G5: =IF(F5<=$AO$19,"Bajo",IF(F5<=$AO$20,"Medio ",IF(F5<=$AO$21,"Alto",0))) -> 0 | H5: =SUM(B5:F5) -> 0 | I5: =IF(H5<=$BA$19,"Bajo",IF(H5<=$BA$20,"Medio ",IF(H5<=$BA$21,"Alto",0))) -> 0 | M5: Nombre de la Dimensión | N5: =B2 -> 0 | Y5: Nombre de la Dimensión | Z5: =D2 -> 0 | AK5: Nombre de la Dimensión | AL5: =F2 -> 0
A6: Beneficiaros 3 | B6: =SUM('Gestión de abastecimiento'!B7:G7) -> 0 | C6: =IF(B6<=$Q$19,"Bajo",IF(B6<=$Q$20,"Medio ",IF(B6<=$Q$21,"Alto",0))) -> 0 | D6: =SUM('Gestión de abastecimiento'!H7:M7) -> 0 | E6: =IF(D6<=$AC$19,"Bajo",IF(D6<=$AC$20,"Medio ",IF(D6<=$AC$21,"Alto",0))) -> 0 | F6: =SUM('Gestión de abastecimiento'!N7:S7) -> 0 | G6: =IF(F6<=$AO$19,"Bajo",IF(F6<=$AO$20,"Medio ",IF(F6<=$AO$21,"Alto",0))) -> 0 | H6: =SUM(B6:F6) -> 0 | I6: =IF(H6<=$BA$19,"Bajo",IF(H6<=$BA$20,"Medio ",IF(H6<=$BA$21,"Alto",0))) -> 0 | M6: Cantidad de Escalas Valorativas | N6: 3 | Y6: Cantidad de Escalas Valorativas | Z6: 3 | AK6: Cantidad de Escalas Valorativas | AL6: 3 | AW6: Cantidad de Escalas Valorativas | AX6: 3
A7: Beneficiaros 4 | B7: =SUM('Gestión de abastecimiento'!B8:G8) -> 0 | C7: =IF(B7<=$Q$19,"Bajo",IF(B7<=$Q$20,"Medio ",IF(B7<=$Q$21,"Alto",0))) -> 0 | D7: =SUM('Gestión de abastecimiento'!H8:M8) -> 0 | E7: =IF(D7<=$AC$19,"Bajo",IF(D7<=$AC$20,"Medio ",IF(D7<=$AC$21,"Alto",0))) -> 0 | F7: =SUM('Gestión de abastecimiento'!N8:S8) -> 0 | G7: =IF(F7<=$AO$19,"Bajo",IF(F7<=$AO$20,"Medio ",IF(F7<=$AO$21,"Alto",0))) -> 0 | H7: =SUM(B7:F7) -> 0 | I7: =IF(H7<=$BA$19,"Bajo",IF(H7<=$BA$20,"Medio ",IF(H7<=$BA$21,"Alto",0))) -> 0 | M7: Nº de Peguntas | N7: 6 | Y7: Nº de Peguntas | Z7: 6 | AK7: Nº de Peguntas | AL7: 6 | AW7: Nº de Peguntas | AX7: 18
A8: Beneficiaros 5 | B8: =SUM('Gestión de abastecimiento'!B9:G9) -> 0 | C8: =IF(B8<=$Q$19,"Bajo",IF(B8<=$Q$20,"Medio ",IF(B8<=$Q$21,"Alto",0))) -> 0 | D8: =SUM('Gestión de abastecimiento'!H9:M9) -> 0 | E8: =IF(D8<=$AC$19,"Bajo",IF(D8<=$AC$20,"Medio ",IF(D8<=$AC$21,"Alto",0))) -> 0 | F8: =SUM('Gestión de abastecimiento'!N9:S9) -> 0 | G8: =IF(F8<=$AO$19,"Bajo",IF(F8<=$AO$20,"Medio ",IF(F8<=$AO$21,"Alto",0))) -> 0 | H8: =SUM(B8:F8) -> 0 | I8: =IF(H8<=$BA$19,"Bajo",IF(H8<=$BA$20,"Medio ",IF(H8<=$BA$21,"Alto",0))) -> 0 | M8: Valor Mínimo por item | N8: 1 | Y8: Valor Mínimo por item | Z8: 1 | AK8: Valor Mínimo por item | AL8: 1 | AW8: Valor Mínimo por item | AX8: 1
A9: Beneficiaros 6 | B9: =SUM('Gestión de abastecimiento'!B10:G10) -> 0 | C9: =IF(B9<=$Q$19,"Bajo",IF(B9<=$Q$20,"Medio ",IF(B9<=$Q$21,"Alto",0))) -> 0 | D9: =SUM('Gestión de abastecimiento'!H10:M10) -> 0 | E9: =IF(D9<=$AC$19,"Bajo",IF(D9<=$AC$20,"Medio ",IF(D9<=$AC$21,"Alto",0))) -> 0 | F9: =SUM('Gestión de abastecimiento'!N10:S10) -> 0 | G9: =IF(F9<=$AO$19,"Bajo",IF(F9<=$AO$20,"Medio ",IF(F9<=$AO$21,"Alto",0))) -> 0 | H9: =SUM(B9:F9) -> 0 | I9: =IF(H9<=$BA$19,"Bajo",IF(H9<=$BA$20,"Medio ",IF(H9<=$BA$21,"Alto",0))) -> 0 | M9: Valor Máximo por item | N9: 5 | Y9: Valor Máximo por item | Z9: 5 | AK9: Valor Máximo por item | AL9: 5 | AW9: Valor Máximo por item | AX9: 5
A10: Beneficiaros 7 | B10: =SUM('Gestión de abastecimiento'!B11:G11) -> 0 | C10: =IF(B10<=$Q$19,"Bajo",IF(B10<=$Q$20,"Medio ",IF(B10<=$Q$21,"Alto",0))) -> 0 | D10: =SUM('Gestión de abastecimiento'!H11:M11) -> 0 | E10: =IF(D10<=$AC$19,"Bajo",IF(D10<=$AC$20,"Medio ",IF(D10<=$AC$21,"Alto",0))) -> 0 | F10: =SUM('Gestión de abastecimiento'!N11:S11) -> 0 | G10: =IF(F10<=$AO$19,"Bajo",IF(F10<=$AO$20,"Medio ",IF(F10<=$AO$21,"Alto",0))) -> 0 | H10: =SUM(B10:F10) -> 0 | I10: =IF(H10<=$BA$19,"Bajo",IF(H10<=$BA$20,"Medio ",IF(H10<=$BA$21,"Alto",0))) -> 0 | M10: Máximo | N10: =N7*N9 -> 0 | Y10: Máximo | Z10: =Z7*Z9 -> 0 | AK10: Máximo | AL10: =AL7*AL9 -> 0 | AW10: Máximo | AX10: =AX7*AX9 -> 0
A11: Beneficiaros 8 | B11: =SUM('Gestión de abastecimiento'!B12:G12) -> 0 | C11: =IF(B11<=$Q$19,"Bajo",IF(B11<=$Q$20,"Medio ",IF(B11<=$Q$21,"Alto",0))) -> 0 | D11: =SUM('Gestión de abastecimiento'!H12:M12) -> 0 | E11: =IF(D11<=$AC$19,"Bajo",IF(D11<=$AC$20,"Medio ",IF(D11<=$AC$21,"Alto",0))) -> 0 | F11: =SUM('Gestión de abastecimiento'!N12:S12) -> 0 | G11: =IF(F11<=$AO$19,"Bajo",IF(F11<=$AO$20,"Medio ",IF(F11<=$AO$21,"Alto",0))) -> 0 | H11: =SUM(B11:F11) -> 0 | I11: =IF(H11<=$BA$19,"Bajo",IF(H11<=$BA$20,"Medio ",IF(H11<=$BA$21,"Alto",0))) -> 0 | M11: Mínimo | N11: =N8*N7 -> 0 | Y11: Mínimo | Z11: =Z8*Z7 -> 0 | AK11: Mínimo | AL11: =AL8*AL7 -> 0 | AW11: Mínimo | AX11: =AX8*AX7 -> 0
A12: Beneficiaros 9 | B12: =SUM('Gestión de abastecimiento'!B13:G13) -> 0 | C12: =IF(B12<=$Q$19,"Bajo",IF(B12<=$Q$20,"Medio ",IF(B12<=$Q$21,"Alto",0))) -> 0 | D12: =SUM('Gestión de abastecimiento'!H13:M13) -> 0 | E12: =IF(D12<=$AC$19,"Bajo",IF(D12<=$AC$20,"Medio ",IF(D12<=$AC$21,"Alto",0))) -> 0 | F12: =SUM('Gestión de abastecimiento'!N13:S13) -> 0 | G12: =IF(F12<=$AO$19,"Bajo",IF(F12<=$AO$20,"Medio ",IF(F12<=$AO$21,"Alto",0))) -> 0 | H12: =SUM(B12:F12) -> 0 | I12: =IF(H12<=$BA$19,"Bajo",IF(H12<=$BA$20,"Medio ",IF(H12<=$BA$21,"Alto",0))) -> 0 | M12: Rango | N12: =N10-N11 -> 0 | Y12: Rango | Z12: =Z10-Z11 -> 0 | AK12: Rango | AL12: =AL10-AL11 -> 0 | AW12: Rango | AX12: =AX10-AX11 -> 0
A13: Beneficiaros 10 | B13: =SUM('Gestión de abastecimiento'!B14:G14) -> 0 | C13: =IF(B13<=$Q$19,"Bajo",IF(B13<=$Q$20,"Medio ",IF(B13<=$Q$21,"Alto",0))) -> 0 | D13: =SUM('Gestión de abastecimiento'!H14:M14) -> 0 | E13: =IF(D13<=$AC$19,"Bajo",IF(D13<=$AC$20,"Medio ",IF(D13<=$AC$21,"Alto",0))) -> 0 | F13: =SUM('Gestión de abastecimiento'!N14:S14) -> 0 | G13: =IF(F13<=$AO$19,"Bajo",IF(F13<=$AO$20,"Medio ",IF(F13<=$AO$21,"Alto",0))) -> 0 | H13: =SUM(B13:F13) -> 0 | I13: =IF(H13<=$BA$19,"Bajo",IF(H13<=$BA$20,"Medio ",IF(H13<=$BA$21,"Alto",0))) -> 0 | M13: Amplitud del Intervalo | N13: =ROUND(N12/N6,0) -> 0 | Y13: Amplitud del Intervalo | Z13: =ROUND(Z12/Z6,0) -> 0 | AK13: Amplitud del Intervalo | AL13: =ROUND(AL12/AL6,0) -> 0 | AW13: Amplitud del Intervalo | AX13: =ROUND(AX12/AX6,0) -> 0
A14: Beneficiaros 11 | B14: =SUM('Gestión de abastecimiento'!B15:G15) -> 0 | C14: =IF(B14<=$Q$19,"Bajo",IF(B14<=$Q$20,"Medio ",IF(B14<=$Q$21,"Alto",0))) -> 0 | D14: =SUM('Gestión de abastecimiento'!H15:M15) -> 0 | E14: =IF(D14<=$AC$19,"Bajo",IF(D14<=$AC$20,"Medio ",IF(D14<=$AC$21,"Alto",0))) -> 0 | F14: =SUM('Gestión de abastecimiento'!N15:S15) -> 0 | G14: =IF(F14<=$AO$19,"Bajo",IF(F14<=$AO$20,"Medio ",IF(F14<=$AO$21,"Alto",0))) -> 0 | H14: =SUM(B14:F14) -> 0 | I14: =IF(H14<=$BA$19,"Bajo",IF(H14<=$BA$20,"Medio ",IF(H14<=$BA$21,"Alto",0))) -> 0
A15: Beneficiaros 12 | B15: =SUM('Gestión de abastecimiento'!B16:G16) -> 0 | C15: =IF(B15<=$Q$19,"Bajo",IF(B15<=$Q$20,"Medio ",IF(B15<=$Q$21,"Alto",0))) -> 0 | D15: =SUM('Gestión de abastecimiento'!H16:M16) -> 0 | E15: =IF(D15<=$AC$19,"Bajo",IF(D15<=$AC$20,"Medio ",IF(D15<=$AC$21,"Alto",0))) -> 0 | F15: =SUM('Gestión de abastecimiento'!N16:S16) -> 0 | G15: =IF(F15<=$AO$19,"Bajo",IF(F15<=$AO$20,"Medio ",IF(F15<=$AO$21,"Alto",0))) -> 0 | H15: =SUM(B15:F15) -> 0 | I15: =IF(H15<=$BA$19,"Bajo",IF(H15<=$BA$20,"Medio ",IF(H15<=$BA$21,"Alto",0))) -> 0 | O15: Tabla 1 | AA15: Tabla 2 | AM15: Tabla 3 | AY15: Tabla 4
A16: Beneficiaros 13 | B16: =SUM('Gestión de abastecimiento'!B17:G17) -> 0 | C16: =IF(B16<=$Q$19,"Bajo",IF(B16<=$Q$20,"Medio ",IF(B16<=$Q$21,"Alto",0))) -> 0 | D16: =SUM('Gestión de abastecimiento'!H17:M17) -> 0 | E16: =IF(D16<=$AC$19,"Bajo",IF(D16<=$AC$20,"Medio ",IF(D16<=$AC$21,"Alto",0))) -> 0 | F16: =SUM('Gestión de abastecimiento'!N17:S17) -> 0 | G16: =IF(F16<=$AO$19,"Bajo",IF(F16<=$AO$20,"Medio ",IF(F16<=$AO$21,"Alto",0))) -> 0 | H16: =SUM(B16:F16) -> 0 | I16: =IF(H16<=$BA$19,"Bajo",IF(H16<=$BA$20,"Medio ",IF(H16<=$BA$21,"Alto",0))) -> 0 | O16: =N5 -> 0 | AA16: =Z5 -> 0 | AM16: =AL5 -> 0 | AY16: =AX4 -> 0
A17: Beneficiaros 14 | B17: =SUM('Gestión de abastecimiento'!B18:G18) -> 0 | C17: =IF(B17<=$Q$19,"Bajo",IF(B17<=$Q$20,"Medio ",IF(B17<=$Q$21,"Alto",0))) -> 0 | D17: =SUM('Gestión de abastecimiento'!H18:M18) -> 0 | E17: =IF(D17<=$AC$19,"Bajo",IF(D17<=$AC$20,"Medio ",IF(D17<=$AC$21,"Alto",0))) -> 0 | F17: =SUM('Gestión de abastecimiento'!N18:S18) -> 0 | G17: =IF(F17<=$AO$19,"Bajo",IF(F17<=$AO$20,"Medio ",IF(F17<=$AO$21,"Alto",0))) -> 0 | H17: =SUM(B17:F17) -> 0 | I17: =IF(H17<=$BA$19,"Bajo",IF(H17<=$BA$20,"Medio ",IF(H17<=$BA$21,"Alto",0))) -> 0 | O17: Calificación | P17: Rango | R17: Frec. | S17: % | AA17: Calificación | AB17: Rango | AD17: Frec. | AE17: % | AM17: Calificación | AN17: Rango | AP17: Frec. | AQ17: % | AY17: Calificación | AZ17: Rango | BB17: Frec. | BC17: %
A18: Beneficiaros 15 | B18: =SUM('Gestión de abastecimiento'!B19:G19) -> 0 | C18: =IF(B18<=$Q$19,"Bajo",IF(B18<=$Q$20,"Medio ",IF(B18<=$Q$21,"Alto",0))) -> 0 | D18: =SUM('Gestión de abastecimiento'!H19:M19) -> 0 | E18: =IF(D18<=$AC$19,"Bajo",IF(D18<=$AC$20,"Medio ",IF(D18<=$AC$21,"Alto",0))) -> 0 | F18: =SUM('Gestión de abastecimiento'!N19:S19) -> 0 | G18: =IF(F18<=$AO$19,"Bajo",IF(F18<=$AO$20,"Medio ",IF(F18<=$AO$21,"Alto",0))) -> 0 | H18: =SUM(B18:F18) -> 0 | I18: =IF(H18<=$BA$19,"Bajo",IF(H18<=$BA$20,"Medio ",IF(H18<=$BA$21,"Alto",0))) -> 0 | P18: Desde | Q18: Hasta | AB18: Desde | AC18: Hasta | AN18: Desde | AO18: Hasta | AZ18: Desde | BA18: Hasta
A19: Beneficiaros 16 | B19: =SUM('Gestión de abastecimiento'!B20:G20) -> 0 | C19: =IF(B19<=$Q$19,"Bajo",IF(B19<=$Q$20,"Medio ",IF(B19<=$Q$21,"Alto",0))) -> 0 | D19: =SUM('Gestión de abastecimiento'!H20:M20) -> 0 | E19: =IF(D19<=$AC$19,"Bajo",IF(D19<=$AC$20,"Medio ",IF(D19<=$AC$21,"Alto",0))) -> 0 | F19: =SUM('Gestión de abastecimiento'!N20:S20) -> 0 | G19: =IF(F19<=$AO$19,"Bajo",IF(F19<=$AO$20,"Medio ",IF(F19<=$AO$21,"Alto",0))) -> 0 | H19: =SUM(B19:F19) -> 0 | I19: =IF(H19<=$BA$19,"Bajo",IF(H19<=$BA$20,"Medio ",IF(H19<=$BA$21,"Alto",0))) -> 0 | O19: Bajo | P19: =N11 -> 0 | Q19: =P19+N13 -> 0 | R19: =COUNTIF($C$4:$C$292,$O19) -> 0 | S19: =R19/R22 -> 0 | AA19: Bajo | AB19: =Z11 -> 0 | AC19: =AB19+Z13 -> 0 | AD19: =COUNTIF($E$4:$E$292,$AA19) -> 0 | AE19: =AD19/AD22 -> 0 | AM19: Bajo | AN19: =AL11 -> 0 | AO19: =AN19+AL13 -> 0 | AP19: =COUNTIF($G$4:$G$292,$AM19) -> 0 | AQ19: =AP19/AP22 -> 0 | AY19: Bajo | AZ19: =AX11 -> 0 | BA19: =AZ19+AX13 - 1 -> 0 | BB19: =COUNTIF($I$4:$I$292,$AY19) -> 0 | BC19: =BB19/BB22 -> 0
A20: Beneficiaros 17 | B20: =SUM('Gestión de abastecimiento'!B21:G21) -> 0 | C20: =IF(B20<=$Q$19,"Bajo",IF(B20<=$Q$20,"Medio ",IF(B20<=$Q$21,"Alto",0))) -> 0 | D20: =SUM('Gestión de abastecimiento'!H21:M21) -> 0 | E20: =IF(D20<=$AC$19,"Bajo",IF(D20<=$AC$20,"Medio ",IF(D20<=$AC$21,"Alto",0))) -> 0 | F20: =SUM('Gestión de abastecimiento'!N21:S21) -> 0 | G20: =IF(F20<=$AO$19,"Bajo",IF(F20<=$AO$20,"Medio ",IF(F20<=$AO$21,"Alto",0))) -> 0 | H20: =SUM(B20:F20) -> 0 | I20: =IF(H20<=$BA$19,"Bajo",IF(H20<=$BA$20,"Medio ",IF(H20<=$BA$21,"Alto",0))) -> 0 | O20: Medio | P20: =Q19+ 1 -> 0 | Q20: =P20+N13 -> 0 | R20: =COUNTIF($C$4:$C$292,$O20) -> 0 | S20: =R20/R22 -> 0 | AA20: Medio | AB20: =AC19+ 1 -> 0 | AC20: =AB20+Z13 -> 0 | AD20: =COUNTIF($E$4:$E$292,$AA20) -> 0 | AE20: =AD20/AD22 -> 0 | AM20: Medio | AN20: =AO19+ 1 -> 0 | AO20: =AN20+AL13 -> 0 | AP20: =COUNTIF($G$4:$G$292,$AM20) -> 0 | AQ20: =AP20/AP22 -> 0 | AY20: Medio | AZ20: =BA19+ 1 -> 0 | BA20: =AZ20+AX13 - 1 -> 0 | BB20: =COUNTIF($I$4:$I$292,$AY20) -> 0 | BC20: =BB20/BB22 -> 0
A21: Beneficiaros 18 | B21: =SUM('Gestión de abastecimiento'!B22:G22) -> 0 | C21: =IF(B21<=$Q$19,"Bajo",IF(B21<=$Q$20,"Medio ",IF(B21<=$Q$21,"Alto",0))) -> 0 | D21: =SUM('Gestión de abastecimiento'!H22:M22) -> 0 | E21: =IF(D21<=$AC$19,"Bajo",IF(D21<=$AC$20,"Medio ",IF(D21<=$AC$21,"Alto",0))) -> 0 | F21: =SUM('Gestión de abastecimiento'!N22:S22) -> 0 | G21: =IF(F21<=$AO$19,"Bajo",IF(F21<=$AO$20,"Medio ",IF(F21<=$AO$21,"Alto",0))) -> 0 | H21: =SUM(B21:F21) -> 0 | I21: =IF(H21<=$BA$19,"Bajo",IF(H21<=$BA$20,"Medio ",IF(H21<=$BA$21,"Alto",0))) -> 0 | O21: Alto | P21: =Q20+ 1 -> 0 | Q21: =N10 -> 0 | R21: =COUNTIF($C$4:$C$292,$O21) -> 0 | S21: =R21/R22 -> 0 | AA21: Alto | AB21: =AC20+ 1 -> 0 | AC21: =Z10 -> 0 | AD21: =COUNTIF($E$4:$E$292,$AA21) -> 0 | AE21: =AD21/AD22 -> 0 | AM21: Alto | AN21: =AO20+ 1 -> 0 | AO21: =AL10 -> 0 | AP21: =COUNTIF($G$4:$G$292,$AM21) -> 0 | AQ21: =AP21/AP22 -> 0 | AY21: Alto | AZ21: =BA20+ 1 -> 0 | BA21: =AX10 -> 0 | BB21: =COUNTIF($I$4:$I$292,$AY21) -> 0 | BC21: =BB21/BB22 -> 0
A22: Beneficiaros 19 | B22: =SUM('Gestión de abastecimiento'!B23:G23) -> 0 | C22: =IF(B22<=$Q$19,"Bajo",IF(B22<=$Q$20,"Medio ",IF(B22<=$Q$21,"Alto",0))) -> 0 | D22: =SUM('Gestión de abastecimiento'!H23:M23) -> 0 | E22: =IF(D22<=$AC$19,"Bajo",IF(D22<=$AC$20,"Medio ",IF(D22<=$AC$21,"Alto",0))) -> 0 | F22: =SUM('Gestión de abastecimiento'!N23:S23) -> 0 | G22: =IF(F22<=$AO$19,"Bajo",IF(F22<=$AO$20,"Medio ",IF(F22<=$AO$21,"Alto",0))) -> 0 | H22: =SUM(B22:F22) -> 0 | I22: =IF(H22<=$BA$19,"Bajo",IF(H22<=$BA$20,"Medio ",IF(H22<=$BA$21,"Alto",0))) -> 0 | O22: Total | R22: =SUM(R19:R21) -> 0 | S22: =SUM(S19:S21) -> 0 | AA22: Total | AD22: =SUM(AD19:AD21) -> 0 | AE22: =SUM(AE19:AE21) -> 0 | AM22: Total | AP22: =SUM(AP19:AP21) -> 0 | AQ22: =SUM(AQ19:AQ21) -> 0 | AY22: Total | BB22: =SUM(BB19:BB21) -> 0 | BC22: =SUM(BC19:BC21) -> 0
A23: Beneficiaros 20 | B23: =SUM('Gestión de abastecimiento'!B24:G24) -> 0 | C23: =IF(B23<=$Q$19,"Bajo",IF(B23<=$Q$20,"Medio ",IF(B23<=$Q$21,"Alto",0))) -> 0 | D23: =SUM('Gestión de abastecimiento'!H24:M24) -> 0 | E23: =IF(D23<=$AC$19,"Bajo",IF(D23<=$AC$20,"Medio ",IF(D23<=$AC$21,"Alto",0))) -> 0 | F23: =SUM('Gestión de abastecimiento'!N24:S24) -> 0 | G23: =IF(F23<=$AO$19,"Bajo",IF(F23<=$AO$20,"Medio ",IF(F23<=$AO$21,"Alto",0))) -> 0 | H23: =SUM(B23:F23) -> 0 | I23: =IF(H23<=$BA$19,"Bajo",IF(H23<=$BA$20,"Medio ",IF(H23<=$BA$21,"Alto",0))) -> 0 | O23: Fuente: Encuesta aplicada | AA23: Fuente: Encuesta aplicada | AM23: Fuente: Encuesta aplicada | AY23: Fuente: Encuesta aplicada
A24: Beneficiaros 21 | B24: =SUM('Gestión de abastecimiento'!B25:G25) -> 0 | C24: =IF(B24<=$Q$19,"Bajo",IF(B24<=$Q$20,"Medio ",IF(B24<=$Q$21,"Alto",0))) -> 0 | D24: =SUM('Gestión de abastecimiento'!H25:M25) -> 0 | E24: =IF(D24<=$AC$19,"Bajo",IF(D24<=$AC$20,"Medio ",IF(D24<=$AC$21,"Alto",0))) -> 0 | F24: =SUM('Gestión de abastecimiento'!N25:S25) -> 0 | G24: =IF(F24<=$AO$19,"Bajo",IF(F24<=$AO$20,"Medio ",IF(F24<=$AO$21,"Alto",0))) -> 0 | H24: =SUM(B24:F24) -> 0 | I24: =IF(H24<=$BA$19,"Bajo",IF(H24<=$BA$20,"Medio ",IF(H24<=$BA$21,"Alto",0))) -> 0 | O24: Elaboración: Propia | AA24: Elaboración: Propia | AM24: Elaboración: Propia | AY24: Elaboración: Propia
A25: Beneficiaros 22 | B25: =SUM('Gestión de abastecimiento'!B26:G26) -> 0 | C25: =IF(B25<=$Q$19,"Bajo",IF(B25<=$Q$20,"Medio ",IF(B25<=$Q$21,"Alto",0))) -> 0 | D25: =SUM('Gestión de abastecimiento'!H26:M26) -> 0 | E25: =IF(D25<=$AC$19,"Bajo",IF(D25<=$AC$20,"Medio ",IF(D25<=$AC$21,"Alto",0))) -> 0 | F25: =SUM('Gestión de abastecimiento'!N26:S26) -> 0 | G25: =IF(F25<=$AO$19,"Bajo",IF(F25<=$AO$20,"Medio ",IF(F25<=$AO$21,"Alto",0))) -> 0 | H25: =SUM(B25:F25) -> 0 | I25: =IF(H25<=$BA$19,"Bajo",IF(H25<=$BA$20,"Medio ",IF(H25<=$BA$21,"Alto",0))) -> 0
A26: Beneficiaros 23 | B26: =SUM('Gestión de abastecimiento'!B27:G27) -> 0 | C26: =IF(B26<=$Q$19,"Bajo",IF(B26<=$Q$20,"Medio ",IF(B26<=$Q$21,"Alto",0))) -> 0 | D26: =SUM('Gestión de abastecimiento'!H27:M27) -> 0 | E26: =IF(D26<=$AC$19,"Bajo",IF(D26<=$AC$20,"Medio ",IF(D26<=$AC$21,"Alto",0))) -> 0 | F26: =SUM('Gestión de abastecimiento'!N27:S27) -> 0 | G26: =IF(F26<=$AO$19,"Bajo",IF(F26<=$AO$20,"Medio ",IF(F26<=$AO$21,"Alto",0))) -> 0 | H26: =SUM(B26:F26) -> 0 | I26: =IF(H26<=$BA$19,"Bajo",IF(H26<=$BA$20,"Medio ",IF(H26<=$BA$21,"Alto",0))) -> 0
A27: Beneficiaros 24 | B27: =SUM('Gestión de abastecimiento'!B28:G28) -> 0 | C27: =IF(B27<=$Q$19,"Bajo",IF(B27<=$Q$20,"Medio ",IF(B27<=$Q$21,"Alto",0))) -> 0 | D27: =SUM('Gestión de abastecimiento'!H28:M28) -> 0 | E27: =IF(D27<=$AC$19,"Bajo",IF(D27<=$AC$20,"Medio ",IF(D27<=$AC$21,"Alto",0))) -> 0 | F27: =SUM('Gestión de abastecimiento'!N28:S28) -> 0 | G27: =IF(F27<=$AO$19,"Bajo",IF(F27<=$AO$20,"Medio ",IF(F27<=$AO$21,"Alto",0))) -> 0 | H27: =SUM(B27:F27) -> 0 | I27: =IF(H27<=$BA$19,"Bajo",IF(H27<=$BA$20,"Medio ",IF(H27<=$BA$21,"Alto",0))) -> 0
A28: Beneficiaros 25 | B28: =SUM('Gestión de abastecimiento'!B29:G29) -> 0 | C28: =IF(B28<=$Q$19,"Bajo",IF(B28<=$Q$20,"Medio ",IF(B28<=$Q$21,"Alto",0))) -> 0 | D28: =SUM('Gestión de abastecimiento'!H29:M29) -> 0 | E28: =IF(D28<=$AC$19,"Bajo",IF(D28<=$AC$20,"Medio ",IF(D28<=$AC$21,"Alto",0))) -> 0 | F28: =SUM('Gestión de abastecimiento'!N29:S29) -> 0 | G28: =IF(F28<=$AO$19,"Bajo",IF(F28<=$AO$20,"Medio ",IF(F28<=$AO$21,"Alto",0))) -> 0 | H28: =SUM(B28:F28) -> 0 | I28: =IF(H28<=$BA$19,"Bajo",IF(H28<=$BA$20,"Medio ",IF(H28<=$BA$21,"Alto",0))) -> 0
A29: Beneficiaros 26 | B29: =SUM('Gestión de abastecimiento'!B30:G30) -> 0 | C29: =IF(B29<=$Q$19,"Bajo",IF(B29<=$Q$20,"Medio ",IF(B29<=$Q$21,"Alto",0))) -> 0 | D29: =SUM('Gestión de abastecimiento'!H30:M30) -> 0 | E29: =IF(D29<=$AC$19,"Bajo",IF(D29<=$AC$20,"Medio ",IF(D29<=$AC$21,"Alto",0))) -> 0 | F29: =SUM('Gestión de abastecimiento'!N30:S30) -> 0 | G29: =IF(F29<=$AO$19,"Bajo",IF(F29<=$AO$20,"Medio ",IF(F29<=$AO$21,"Alto",0))) -> 0 | H29: =SUM(B29:F29) -> 0 | I29: =IF(H29<=$BA$19,"Bajo",IF(H29<=$BA$20,"Medio ",IF(H29<=$BA$21,"Alto",0))) -> 0
A30: Beneficiaros 27 | B30: =SUM('Gestión de abastecimiento'!B31:G31) -> 0 | C30: =IF(B30<=$Q$19,"Bajo",IF(B30<=$Q$20,"Medio ",IF(B30<=$Q$21,"Alto",0))) -> 0 | D30: =SUM('Gestión de abastecimiento'!H31:M31) -> 0 | E30: =IF(D30<=$AC$19,"Bajo",IF(D30<=$AC$20,"Medio ",IF(D30<=$AC$21,"Alto",0))) -> 0 | F30: =SUM('Gestión de abastecimiento'!N31:S31) -> 0 | G30: =IF(F30<=$AO$19,"Bajo",IF(F30<=$AO$20,"Medio ",IF(F30<=$AO$21,"Alto",0))) -> 0 | H30: =SUM(B30:F30) -> 0 | I30: =IF(H30<=$BA$19,"Bajo",IF(H30<=$BA$20,"Medio ",IF(H30<=$BA$21,"Alto",0))) -> 0
A31: Beneficiaros 28 | B31: =SUM('Gestión de abastecimiento'!B32:G32) -> 0 | C31: =IF(B31<=$Q$19,"Bajo",IF(B31<=$Q$20,"Medio ",IF(B31<=$Q$21,"Alto",0))) -> 0 | D31: =SUM('Gestión de abastecimiento'!H32:M32) -> 0 | E31: =IF(D31<=$AC$19,"Bajo",IF(D31<=$AC$20,"Medio ",IF(D31<=$AC$21,"Alto",0))) -> 0 | F31: =SUM('Gestión de abastecimiento'!N32:S32) -> 0 | G31: =IF(F31<=$AO$19,"Bajo",IF(F31<=$AO$20,"Medio ",IF(F31<=$AO$21,"Alto",0))) -> 0 | H31: =SUM(B31:F31) -> 0 | I31: =IF(H31<=$BA$19,"Bajo",IF(H31<=$BA$20,"Medio ",IF(H31<=$BA$21,"Alto",0))) -> 0
A32: Beneficiaros 29 | B32: =SUM('Gestión de abastecimiento'!B33:G33) -> 0 | C32: =IF(B32<=$Q$19,"Bajo",IF(B32<=$Q$20,"Medio ",IF(B32<=$Q$21,"Alto",0))) -> 0 | D32: =SUM('Gestión de abastecimiento'!H33:M33) -> 0 | E32: =IF(D32<=$AC$19,"Bajo",IF(D32<=$AC$20,"Medio ",IF(D32<=$AC$21,"Alto",0))) -> 0 | F32: =SUM('Gestión de abastecimiento'!N33:S33) -> 0 | G32: =IF(F32<=$AO$19,"Bajo",IF(F32<=$AO$20,"Medio ",IF(F32<=$AO$21,"Alto",0))) -> 0 | H32: =SUM(B32:F32) -> 0 | I32: =IF(H32<=$BA$19,"Bajo",IF(H32<=$BA$20,"Medio ",IF(H32<=$BA$21,"Alto",0))) -> 0
A33: Beneficiaros 30 | B33: =SUM('Gestión de abastecimiento'!B34:G34) -> 0 | C33: =IF(B33<=$Q$19,"Bajo",IF(B33<=$Q$20,"Medio ",IF(B33<=$Q$21,"Alto",0))) -> 0 | D33: =SUM('Gestión de abastecimiento'!H34:M34) -> 0 | E33: =IF(D33<=$AC$19,"Bajo",IF(D33<=$AC$20,"Medio ",IF(D33<=$AC$21,"Alto",0))) -> 0 | F33: =SUM('Gestión de abastecimiento'!N34:S34) -> 0 | G33: =IF(F33<=$AO$19,"Bajo",IF(F33<=$AO$20,"Medio ",IF(F33<=$AO$21,"Alto",0))) -> 0 | H33: =SUM(B33:F33) -> 0 | I33: =IF(H33<=$BA$19,"Bajo",IF(H33<=$BA$20,"Medio ",IF(H33<=$BA$21,"Alto",0))) -> 0
A34: Beneficiaros 31 | B34: =SUM('Gestión de abastecimiento'!B35:G35) -> 0 | C34: =IF(B34<=$Q$19,"Bajo",IF(B34<=$Q$20,"Medio ",IF(B34<=$Q$21,"Alto",0))) -> 0 | D34: =SUM('Gestión de abastecimiento'!H35:M35) -> 0 | E34: =IF(D34<=$AC$19,"Bajo",IF(D34<=$AC$20,"Medio ",IF(D34<=$AC$21,"Alto",0))) -> 0 | F34: =SUM('Gestión de abastecimiento'!N35:S35) -> 0 | G34: =IF(F34<=$AO$19,"Bajo",IF(F34<=$AO$20,"Medio ",IF(F34<=$AO$21,"Alto",0))) -> 0 | H34: =SUM(B34:F34) -> 0 | I34: =IF(H34<=$BA$19,"Bajo",IF(H34<=$BA$20,"Medio ",IF(H34<=$BA$21,"Alto",0))) -> 0
A35: Beneficiaros 32 | B35: =SUM('Gestión de abastecimiento'!B36:G36) -> 0 | C35: =IF(B35<=$Q$19,"Bajo",IF(B35<=$Q$20,"Medio ",IF(B35<=$Q$21,"Alto",0))) -> 0 | D35: =SUM('Gestión de abastecimiento'!H36:M36) -> 0 | E35: =IF(D35<=$AC$19,"Bajo",IF(D35<=$AC$20,"Medio ",IF(D35<=$AC$21,"Alto",0))) -> 0 | F35: =SUM('Gestión de abastecimiento'!N36:S36) -> 0 | G35: =IF(F35<=$AO$19,"Bajo",IF(F35<=$AO$20,"Medio ",IF(F35<=$AO$21,"Alto",0))) -> 0 | H35: =SUM(B35:F35) -> 0 | I35: =IF(H35<=$BA$19,"Bajo",IF(H35<=$BA$20,"Medio ",IF(H35<=$BA$21,"Alto",0))) -> 0
A36: Beneficiaros 33 | B36: =SUM('Gestión de abastecimiento'!B37:G37) -> 0 | C36: =IF(B36<=$Q$19,"Bajo",IF(B36<=$Q$20,"Medio ",IF(B36<=$Q$21,"Alto",0))) -> 0 | D36: =SUM('Gestión de abastecimiento'!H37:M37) -> 0 | E36: =IF(D36<=$AC$19,"Bajo",IF(D36<=$AC$20,"Medio ",IF(D36<=$AC$21,"Alto",0))) -> 0 | F36: =SUM('Gestión de abastecimiento'!N37:S37) -> 0 | G36: =IF(F36<=$AO$19,"Bajo",IF(F36<=$AO$20,"Medio ",IF(F36<=$AO$21,"Alto",0))) -> 0 | H36: =SUM(B36:F36) -> 0 | I36: =IF(H36<=$BA$19,"Bajo",IF(H36<=$BA$20,"Medio ",IF(H36<=$BA$21,"Alto",0))) -> 0
... A42: Beneficiaros 39 | B42: =SUM('Gestión de abastecimiento'!B43:G43) -> 0 | C42: =IF(B42<=$Q$19,"Bajo",IF(B42<=$Q$20,"Medio ",IF(B42<=$Q$21,"Alto",0))) -> 0 | D42: =SUM('Gestión de abastecimiento'!H43:M43) -> 0 | E42: =IF(D42<=$AC$19,"Bajo",IF(D42<=$AC$20,"Medio ",IF(D42<=$AC$21,"Alto",0))) -> 0 | F42: =SUM('Gestión de abastecimiento'!N43:S43) -> 0 | G42: =IF(F42<=$AO$19,"Bajo",IF(F42<=$AO$20,"Medio ",IF(F42<=$AO$21,"Alto",0))) -> 0 | H42: =SUM(B42:F42) -> 0 | I42: =IF(H42<=$BA$19,"Bajo",IF(H42<=$BA$20,"Medio ",IF(H42<=$BA$21,"Alto",0))) -> 0
A43: Beneficiaros 40 | B43: =SUM('Gestión de abastecimiento'!B44:G44) -> 0 | C43: =IF(B43<=$Q$19,"Bajo",IF(B43<=$Q$20,"Medio ",IF(B43<=$Q$21,"Alto",0))) -> 0 | D43: =SUM('Gestión de abastecimiento'!H44:M44) -> 0 | E43: =IF(D43<=$AC$19,"Bajo",IF(D43<=$AC$20,"Medio ",IF(D43<=$AC$21,"Alto",0))) -> 0 | F43: =SUM('Gestión de abastecimiento'!N44:S44) -> 0 | G43: =IF(F43<=$AO$19,"Bajo",IF(F43<=$AO$20,"Medio ",IF(F43<=$AO$21,"Alto",0))) -> 0 | H43: =SUM(B43:F43) -> 0 | I43: =IF(H43<=$BA$19,"Bajo",IF(H43<=$BA$20,"Medio ",IF(H43<=$BA$21,"Alto",0))) -> 0 | O43: Figura.1 | AA43: Figura.2 | AM43: Figura.3 | AY43: Figura.4
A44: Beneficiaros 41 | B44: =SUM('Gestión de abastecimiento'!B45:G45) -> 0 | C44: =IF(B44<=$Q$19,"Bajo",IF(B44<=$Q$20,"Medio ",IF(B44<=$Q$21,"Alto",0))) -> 0 | D44: =SUM('Gestión de abastecimiento'!H45:M45) -> 0 | E44: =IF(D44<=$AC$19,"Bajo",IF(D44<=$AC$20,"Medio ",IF(D44<=$AC$21,"Alto",0))) -> 0 | F44: =SUM('Gestión de abastecimiento'!N45:S45) -> 0 | G44: =IF(F44<=$AO$19,"Bajo",IF(F44<=$AO$20,"Medio ",IF(F44<=$AO$21,"Alto",0))) -> 0 | H44: =SUM(B44:F44) -> 0 | I44: =IF(H44<=$BA$19,"Bajo",IF(H44<=$BA$20,"Medio ",IF(H44<=$BA$21,"Alto",0))) -> 0 | O44: Planificación | AA44: Transparencia | AM44: Cumplimiento normativo | AY44: Planificación
A45: Beneficiaros 42 | B45: =SUM('Gestión de abastecimiento'!B46:G46) -> 0 | C45: =IF(B45<=$Q$19,"Bajo",IF(B45<=$Q$20,"Medio ",IF(B45<=$Q$21,"Alto",0))) -> 0 | D45: =SUM('Gestión de abastecimiento'!H46:M46) -> 0 | E45: =IF(D45<=$AC$19,"Bajo",IF(D45<=$AC$20,"Medio ",IF(D45<=$AC$21,"Alto",0))) -> 0 | F45: =SUM('Gestión de abastecimiento'!N46:S46) -> 0 | G45: =IF(F45<=$AO$19,"Bajo",IF(F45<=$AO$20,"Medio ",IF(F45<=$AO$21,"Alto",0))) -> 0 | H45: =SUM(B45:F45) -> 0 | I45: =IF(H45<=$BA$19,"Bajo",IF(H45<=$BA$20,"Medio ",IF(H45<=$BA$21,"Alto",0))) -> 0
...

Sheet Tabulacion por item
D4: Item 1 | M4: Item 2 | V4: Item 3 | AE4: Item 4 | AN4: Item 5 | AW4: Item 6 | BF4: Item 7 | BO4: Item 8 | BX4: Item 9 | CG4: Item 10 | CP4: Item 11 | CY4: Item 12 | DH4: Item 13 | DQ4: Item 14 | DZ4: Item 15 | EI4: Item 16 | ER4: Item 17 | FA4: Item 18
D5: Tabla 1 | M5: Tabla 2 | V5: Tabla 3 | AE5: Tabla 4 | AN5: Tabla 5 | AW5: Tabla 6 | BF5: Tabla 7 | BO5: Tabla 8 | BX5: Tabla 9 | CG5: Tabla 10 | CP5: Tabla 11 | CY5: Tabla 12 | DH5: Tabla 13 | DQ5: Tabla 14 | DZ5: Tabla 15 | EI5: Tabla 16 | ER5: Tabla 17 | FA5: Tabla 18
D6: x | M6: x | V6: x | AE6: x | AW6: x | BF6: x | BO6: x | BX6: x | CG6: x | CP6: x | CY6: x | DH6: x | DQ6: x | DZ6: x | EI6: x | ER6: x | FA6: x
E7: Frec. | F7: % | N7: Frec. | O7: % | W7: Frec. | X7: % | AF7: Frec. | AG7: % | AO7: Frec. | AP7: % | AX7: Frec. | AY7: % | BG7: Frec. | BH7: % | BP7: Frec. | BQ7: % | BY7: Frec. | BZ7: % | CH7: Frec. | CI7: % | CQ7: Frec. | CR7: % | CZ7: Frec. | DA7: % | DI7: Frec. | DJ7: % | DR7: Frec. | DS7: % | EA7: Frec. | EB7: % | EJ7: Frec. | EK7: % | ES7: Frec. | ET7: % | FB7: Frec. | FC7: %
D8: =('Gestión de abastecimiento'!A300) -> 0 | E8: =('Gestión de abastecimiento'!B300) -> 0 | F8: =('Gestión de abastecimiento'!B306) -> 0 | M8: =('Gestión de abastecimiento'!A300) -> 0 | N8: =('Gestión de abastecimiento'!C300) -> 0 | O8: =('Gestión de abastecimiento'!C306) -> 0 | V8: =('Gestión de abastecimiento'!A300) -> 0 | W8: =('Gestión de abastecimiento'!D300) -> 0 | X8: =('Gestión de abastecimiento'!D306) -> 0 | AE8: =('Gestión de abastecimiento'!A300) -> 0 | AF8: =('Gestión de abastecimiento'!E300) -> 0 | AG8: =('Gestión de abastecimiento'!E306) -> 0 | AN8: =('Gestión de abastecimiento'!A300) -> 0 | AO8: =('Gestión de abastecimiento'!F300) -> 0 | AP8: =('Gestión de abastecimiento'!F306) -> 0 | AW8: =('Gestión de abastecimiento'!A300) -> 0 | AX8: =('Gestión de abastecimiento'!G300) -> 0 | AY8: =('Gestión de abastecimiento'!G306) -> 0 | BF8: =('Gestión de abastecimiento'!A300) -> 0 | BG8: =('Gestión de abastecimiento'!H300) -> 0 | BH8: =('Gestión de abastecimiento'!H306) -> 0 | BO8: =('Gestión de abastecimiento'!A300) -> 0 | BP8: =('Gestión de abastecimiento'!I300) -> 0 | BQ8: =('Gestión de abastecimiento'!I306) -> 0 | BX8: =('Gestión de abastecimiento'!A300) -> 0 | BY8: =('Gestión de abastecimiento'!J300) -> 0 | BZ8: =('Gestión de abastecimiento'!J306) -> 0 | CG8: =('Gestión de abastecimiento'!A300) -> 0 | CH8: =('Gestión de abastecimiento'!K300) -> 0 | CI8: =('Gestión de abastecimiento'!K306) -> 0 | CP8: =('Gestión de abastecimiento'!A300) -> 0 | CQ8: =('Gestión de abastecimiento'!L300) -> 0 | CR8: =('Gestión de abastecimiento'!L306) -> 0 | CY8: =('Gestión de abastecimiento'!A300) -> 0 | CZ8: =('Gestión de abastecimiento'!M300) -> 0 | DA8: =('Gestión de abastecimiento'!M306) -> 0 | DH8: =('Gestión de abastecimiento'!A300) -> 0 | DI8: =('Gestión de abastecimiento'!N300) -> 0 | DJ8: =('Gestión de abastecimiento'!N306) -> 0 | DQ8: =('Gestión de abastecimiento'!A300) -> 0 | DR8: =('Gestión de abastecimiento'!O300) -> 0 | DS8: =('Gestión de abastecimiento'!O306) -> 0 | DZ8: =('Gestión de abastecimiento'!A300) -> 0 | EA8: =('Gestión de abastecimiento'!P300) -> 0 | EB8: =('Gestión de abastecimiento'!P306) -> 0 | EI8: =('Gestión de abastecimiento'!A300) -> 0 | EJ8: =('Gestión de abastecimiento'!Q300) -> 0 | EK8: =('Gestión de abastecimiento'!Q306) -> 0 | ER8: =('Gestión de abastecimiento'!A300) -> 0 | ES8: =('Gestión de abastecimiento'!R300) -> 0 | ET8: =('Gestión de abastecimiento'!R306) -> 0 | FA8: =('Gestión de abastecimiento'!A300) -> 0 | FB8: =('Gestión de abastecimiento'!S300) -> 0 | FC8: =('Gestión de abastecimiento'!S306) -> 0
D9: =('Gestión de abastecimiento'!A301) -> 0 | E9: =('Gestión de abastecimiento'!B301) -> 0 | F9: =('Gestión de abastecimiento'!B307) -> 0 | M9: =('Gestión de abastecimiento'!A301) -> 0 | N9: =('Gestión de abastecimiento'!C301) -> 0 | O9: =('Gestión de abastecimiento'!C307) -> 0 | V9: =('Gestión de abastecimiento'!A301) -> 0 | W9: =('Gestión de abastecimiento'!D301) -> 0 | X9: =('Gestión de abastecimiento'!D307) -> 0 | AE9: =('Gestión de abastecimiento'!A301) -> 0 | AF9: =('Gestión de abastecimiento'!E301) -> 0 | AG9: =('Gestión de abastecimiento'!E307) -> 0 | AN9: =('Gestión de abastecimiento'!A301) -> 0 | AO9: =('Gestión de abastecimiento'!F301) -> 0 | AP9: =('Gestión de abastecimiento'!F307) -> 0 | AW9: =('Gestión de abastecimiento'!A301) -> 0 | AX9: =('Gestión de abastecimiento'!G301) -> 0 | AY9: =('Gestión de abastecimiento'!G307) -> 0 | BF9: =('Gestión de abastecimiento'!A301) -> 0 | BG9: =('Gestión de abastecimiento'!H301) -> 0 | BH9: =('Gestión de abastecimiento'!H307) -> 0 | BO9: =('Gestión de abastecimiento'!A301) -> 0 | BP9: =('Gestión de abastecimiento'!I301) -> 0 | BQ9: =('Gestión de abastecimiento'!I307) -> 0 | BX9: =('Gestión de abastecimiento'!A301) -> 0 | BY9: =('Gestión de abastecimiento'!J301) -> 0 | BZ9: =('Gestión de abastecimiento'!J307) -> 0 | CG9: =('Gestión de abastecimiento'!A301) -> 0 | CH9: =('Gestión de abastecimiento'!K301) -> 0 | CI9: =('Gestión de abastecimiento'!K307) -> 0 | CP9: =('Gestión de abastecimiento'!A301) -> 0 | CQ9: =('Gestión de abastecimiento'!L301) -> 0 | CR9: =('Gestión de abastecimiento'!L307) -> 0 | CY9: =('Gestión de abastecimiento'!A301) -> 0 | CZ9: =('Gestión de abastecimiento'!M301) -> 0 | DA9: =('Gestión de abastecimiento'!M307) -> 0 | DH9: =('Gestión de abastecimiento'!A301) -> 0 | DI9: =('Gestión de abastecimiento'!N301) -> 0 | DJ9: =('Gestión de abastecimiento'!N307) -> 0 | DQ9: =('Gestión de abastecimiento'!A301) -> 0 | DR9: =('Gestión de abastecimiento'!O301) -> 0 | DS9: =('Gestión de abastecimiento'!O307) -> 0 | DZ9: =('Gestión de abastecimiento'!A301) -> 0 | EA9: =('Gestión de abastecimiento'!P301) -> 0 | EB9: =('Gestión de abastecimiento'!P307) -> 0 | EI9: =('Gestión de abastecimiento'!A301) -> 0 | EJ9: =('Gestión de abastecimiento'!Q301) -> 0 | EK9: =('Gestión de abastecimiento'!Q307) -> 0 | ER9: =('Gestión de abastecimiento'!A301) -> 0 | ES9: =('Gestión de abastecimiento'!R301) -> 0 | ET9: =('Gestión de abastecimiento'!R307) -> 0 | FA9: =('Gestión de abastecimiento'!A301) -> 0 | FB9: =('Gestión de abastecimiento'!S301) -> 0 | FC9: =('Gestión de abastecimiento'!S307) -> 0
D10: =('Gestión de abastecimiento'!A302) -> 0 | E10: =('Gestión de abastecimiento'!B302) -> 0 | F10: =('Gestión de abastecimiento'!B308) -> 0 | M10: =('Gestión de abastecimiento'!A302) -> 0 | N10: =('Gestión de abastecimiento'!C302) -> 0 | O10: =('Gestión de abastecimiento'!C308) -> 0 | V10: =('Gestión de abastecimiento'!A302) -> 0 | W10: =('Gestión de abastecimiento'!D302) -> 0 | X10: =('Gestión de abastecimiento'!D308) -> 0 | AE10: =('Gestión de abastecimiento'!A302) -> 0 | AF10: =('Gestión de abastecimiento'!E302) -> 0 | AG10: =('Gestión de abastecimiento'!E308) -> 0 | AN10: =('Gestión de abastecimiento'!A302) -> 0 | AO10: =('Gestión de abastecimiento'!F302) -> 0 | AP10: =('Gestión de abastecimiento'!F308) -> 0 | AW10: =('Gestión de abastecimiento'!A302) -> 0 | AX10: =('Gestión de abastecimiento'!G302) -> 0 | AY10: =('Gestión de abastecimiento'!G308) -> 0 | BF10: =('Gestión de abastecimiento'!A302) -> 0 | BG10: =('Gestión de abastecimiento'!H302) -> 0 | BH10: =('Gestión de abastecimiento'!H308) -> 0 | BO10: =('Gestión de abastecimiento'!A302) -> 0 | BP10: =('Gestión de abastecimiento'!I302) -> 0 | BQ10: =('Gestión de abastecimiento'!I308) -> 0 | BX10: =('Gestión de abastecimiento'!A302) -> 0 | BY10: =('Gestión de abastecimiento'!J302) -> 0 | BZ10: =('Gestión de abastecimiento'!J308) -> 0 | CG10: =('Gestión de abastecimiento'!A302) -> 0 | CH10: =('Gestión de abastecimiento'!K302) -> 0 | CI10: =('Gestión de abastecimiento'!K308) -> 0 | CP10: =('Gestión de abastecimiento'!A302) -> 0 | CQ10: =('Gestión de abastecimiento'!L302) -> 0 | CR10: =('Gestión de abastecimiento'!L308) -> 0 | CY10: =('Gestión de abastecimiento'!A302) -> 0 | CZ10: =('Gestión de abastecimiento'!M302) -> 0 | DA10: =('Gestión de abastecimiento'!M308) -> 0 | DH10: =('Gestión de abastecimiento'!A302) -> 0 | DI10: =('Gestión de abastecimiento'!N302) -> 0 | DJ10: =('Gestión de abastecimiento'!N308) -> 0 | DQ10: =('Gestión de abastecimiento'!A302) -> 0 | DR10: =('Gestión de abastecimiento'!O302) -> 0 | DS10: =('Gestión de abastecimiento'!O308) -> 0 | DZ10: =('Gestión de abastecimiento'!A302) -> 0 | EA10: =('Gestión de abastecimiento'!P302) -> 0 | EB10: =('Gestión de abastecimiento'!P308) -> 0 | EI10: =('Gestión de abastecimiento'!A302) -> 0 | EJ10: =('Gestión de abastecimiento'!Q302) -> 0 | EK10: =('Gestión de abastecimiento'!Q308) -> 0 | ER10: =('Gestión de abastecimiento'!A302) -> 0 | ES10: =('Gestión de abastecimiento'!R302) -> 0 | ET10: =('Gestión de abastecimiento'!R308) -> 0 | FA10: =('Gestión de abastecimiento'!A302) -> 0 | FB10: =('Gestión de abastecimiento'!S302) -> 0 | FC10: =('Gestión de abastecimiento'!S308) -> 0
D11: =('Gestión de abastecimiento'!A303) -> 0 | E11: =('Gestión de abastecimiento'!B303) -> 0 | F11: =('Gestión de abastecimiento'!B309) -> 0 | M11: =('Gestión de abastecimiento'!A303) -> 0 | N11: =('Gestión de abastecimiento'!C303) -> 0 | O11: =('Gestión de abastecimiento'!C309) -> 0 | V11: =('Gestión de abastecimiento'!A303) -> 0 | W11: =('Gestión de abastecimiento'!D303) -> 0 | X11: =('Gestión de abastecimiento'!D309) -> 0 | AE11: =('Gestión de abastecimiento'!A303) -> 0 | AF11: =('Gestión de abastecimiento'!E303) -> 0 | AG11: =('Gestión de abastecimiento'!E309) -> 0 | AN11: =('Gestión de abastecimiento'!A303) -> 0 | AO11: =('Gestión de abastecimiento'!F303) -> 0 | AP11: =('Gestión de abastecimiento'!F309) -> 0 | AW11: =('Gestión de abastecimiento'!A303) -> 0 | AX11: =('Gestión de abastecimiento'!G303) -> 0 | AY11: =('Gestión de abastecimiento'!G309) -> 0 | BF11: =('Gestión de abastecimiento'!A303) -> 0 | BG11: =('Gestión de abastecimiento'!H303) -> 0 | BH11: =('Gestión de abastecimiento'!H309) -> 0 | BO11: =('Gestión de abastecimiento'!A303) -> 0 | BP11: =('Gestión de abastecimiento'!I303) -> 0 | BQ11: =('Gestión de abastecimiento'!I309) -> 0 | BX11: =('Gestión de abastecimiento'!A303) -> 0 | BY11: =('Gestión de abastecimiento'!J303) -> 0 | BZ11: =('Gestión de abastecimiento'!J309) -> 0 | CG11: =('Gestión de abastecimiento'!A303) -> 0 | CH11: =('Gestión de abastecimiento'!K303) -> 0 | CI11: =('Gestión de abastecimiento'!K309) -> 0 | CP11: =('Gestión de abastecimiento'!A303) -> 0 | CQ11: =('Gestión de abastecimiento'!L303) -> 0 | CR11: =('Gestión de abastecimiento'!L309) -> 0 | CY11: =('Gestión de abastecimiento'!A303) -> 0 | CZ11: =('Gestión de abastecimiento'!M303) -> 0 | DA11: =('Gestión de abastecimiento'!M309) -> 0 | DH11: =('Gestión de abastecimiento'!A303) -> 0 | DI11: =('Gestión de abastecimiento'!N303) -> 0 | DJ11: =('Gestión de abastecimiento'!N309) -> 0 | DQ11: =('Gestión de abastecimiento'!A303) -> 0 | DR11: =('Gestión de abastecimiento'!O303) -> 0 | DS11: =('Gestión de abastecimiento'!O309) -> 0 | DZ11: =('Gestión de abastecimiento'!A303) -> 0 | EA11: =('Gestión de abastecimiento'!P303) -> 0 | EB11: =('Gestión de abastecimiento'!P309) -> 0 | EI11: =('Gestión de abastecimiento'!A303) -> 0 | EJ11: =('Gestión de abastecimiento'!Q303) -> 0 | EK11: =('Gestión de abastecimiento'!Q309) -> 0 | ER11: =('Gestión de abastecimiento'!A303) -> 0 | ES11: =('Gestión de abastecimiento'!R303) -> 0 | ET11: =('Gestión de abastecimiento'!R309) -> 0 | FA11: =('Gestión de abastecimiento'!A303) -> 0 | FB11: =('Gestión de abastecimiento'!S303) -> 0 | FC11: =('Gestión de abastecimiento'!S309) -> 0
D12: =('Gestión de abastecimiento'!A304) -> 0 | E12: =('Gestión de abastecimiento'!B304) -> 0 | F12: =('Gestión de abastecimiento'!B310) -> 0 | M12: =('Gestión de abastecimiento'!A304) -> 0 | N12: =('Gestión de abastecimiento'!C304) -> 0 | O12: =('Gestión de abastecimiento'!C310) -> 0 | V12: =('Gestión de abastecimiento'!A304) -> 0 | W12: =('Gestión de abastecimiento'!D304) -> 0 | X12: =('Gestión de abastecimiento'!D310) -> 0 | AE12: =('Gestión de abastecimiento'!A304) -> 0 | AF12: =('Gestión de abastecimiento'!E304) -> 0 | AG12: =('Gestión de abastecimiento'!E310) -> 0 | AN12: =('Gestión de abastecimiento'!A304) -> 0 | AO12: =('Gestión de abastecimiento'!F304) -> 0 | AP12: =('Gestión de abastecimiento'!F310) -> 0 | AW12: =('Gestión de abastecimiento'!A304) -> 0 | AX12: =('Gestión de abastecimiento'!G304) -> 0 | AY12: =('Gestión de abastecimiento'!G310) -> 0 | BF12: =('Gestión de abastecimiento'!A304) -> 0 | BG12: =('Gestión de abastecimiento'!H304) -> 0 | BH12: =('Gestión de abastecimiento'!H310) -> 0 | BO12: =('Gestión de abastecimiento'!A304) -> 0 | BP12: =('Gestión de abastecimiento'!I304) -> 0 | BQ12: =('Gestión de abastecimiento'!I310) -> 0 | BX12: =('Gestión de abastecimiento'!A304) -> 0 | BY12: =('Gestión de abastecimiento'!J304) -> 0 | BZ12: =('Gestión de abastecimiento'!J310) -> 0 | CG12: =('Gestión de abastecimiento'!A304) -> 0 | CH12: =('Gestión de abastecimiento'!K304) -> 0 | CI12: =('Gestión de abastecimiento'!K310) -> 0 | CP12: =('Gestión de abastecimiento'!A304) -> 0 | CQ12: =('Gestión de abastecimiento'!L304) -> 0 | CR12: =('Gestión de abastecimiento'!L310) -> 0 | CY12: =('Gestión de abastecimiento'!A304) -> 0 | CZ12: =('Gestión de abastecimiento'!M304) -> 0 | DA12: =('Gestión de abastecimiento'!M310) -> 0 | DH12: =('Gestión de abastecimiento'!A304) -> 0 | DI12: =('Gestión de abastecimiento'!N304) -> 0 | DJ12: =('Gestión de abastecimiento'!N310) -> 0 | DQ12: =('Gestión de abastecimiento'!A304) -> 0 | DR12: =('Gestión de abastecimiento'!O304) -> 0 | DS12: =('Gestión de abastecimiento'!O310) -> 0 | DZ12: =('Gestión de abastecimiento'!A304) -> 0 | EA12: =('Gestión de abastecimiento'!P304) -> 0 | EB12: =('Gestión de abastecimiento'!P310) -> 0 | EI12: =('Gestión de abastecimiento'!A304) -> 0 | EJ12: =('Gestión de abastecimiento'!Q304) -> 0 | EK12: =('Gestión de abastecimiento'!Q310) -> 0 | ER12: =('Gestión de abastecimiento'!A304) -> 0 | ES12: =('Gestión de abastecimiento'!R304) -> 0 | ET12: =('Gestión de abastecimiento'!R310) -> 0 | FA12: =('Gestión de abastecimiento'!A304) -> 0 | FB12: =('Gestión de abastecimiento'!S304) -> 0 | FC12: =('Gestión de abastecimiento'!S310) -> 0
D13: =('Gestión de abastecimiento'!A305) -> 0 | E13: =('Gestión de abastecimiento'!B305) -> 0 | F13: =('Gestión de abastecimiento'!B311) -> 0 | M13: =('Gestión de abastecimiento'!A305) -> 0 | N13: =('Gestión de abastecimiento'!C305) -> 0 | O13: =('Gestión de abastecimiento'!C311) -> 0 | V13: =('Gestión de abastecimiento'!A305) -> 0 | W13: =('Gestión de abastecimiento'!D305) -> 0 | X13: =('Gestión de abastecimiento'!D311) -> 0 | AE13: =('Gestión de abastecimiento'!A305) -> 0 | AF13: =('Gestión de abastecimiento'!E305) -> 0 | AG13: =('Gestión de abastecimiento'!E311) -> 0 | AN13: =('Gestión de abastecimiento'!A305) -> 0 | AO13: =('Gestión de abastecimiento'!F305) -> 0 | AP13: =('Gestión de abastecimiento'!F311) -> 0 | AW13: =('Gestión de abastecimiento'!A305) -> 0 | AX13: =('Gestión de abastecimiento'!G305) -> 0 | AY13: =('Gestión de abastecimiento'!G311) -> 0 | BF13: =('Gestión de abastecimiento'!A305) -> 0 | BG13: =('Gestión de abastecimiento'!H305) -> 0 | BH13: =('Gestión de abastecimiento'!H311) -> 0 | BO13: =('Gestión de abastecimiento'!A305) -> 0 | BP13: =('Gestión de abastecimiento'!I305) -> 0 | BQ13: =('Gestión de abastecimiento'!I311) -> 0 | BX13: =('Gestión de abastecimiento'!A305) -> 0 | BY13: =('Gestión de abastecimiento'!J305) -> 0 | BZ13: =('Gestión de abastecimiento'!J311) -> 0 | CG13: =('Gestión de abastecimiento'!A305) -> 0 | CH13: =('Gestión de abastecimiento'!K305) -> 0 | CI13: =('Gestión de abastecimiento'!K311) -> 0 | CP13: =('Gestión de abastecimiento'!A305) -> 0 | CQ13: =('Gestión de abastecimiento'!L305) -> 0 | CR13: =('Gestión de abastecimiento'!L311) -> 0 | CY13: =('Gestión de abastecimiento'!A305) -> 0 | CZ13: =('Gestión de abastecimiento'!M305) -> 0 | DA13: =('Gestión de abastecimiento'!M311) -> 0 | DH13: =('Gestión de abastecimiento'!A305) -> 0 | DI13: =('Gestión de abastecimiento'!N305) -> 0 | DJ13: =('Gestión de abastecimiento'!N311) -> 0 | DQ13: =('Gestión de abastecimiento'!A305) -> 0 | DR13: =('Gestión de abastecimiento'!O305) -> 0 | DS13: =('Gestión de abastecimiento'!O311) -> 0 | DZ13: =('Gestión de abastecimiento'!A305) -> 0 | EA13: =('Gestión de abastecimiento'!P305) -> 0 | EB13: =('Gestión de abastecimiento'!P311) -> 0 | EI13: =('Gestión de abastecimiento'!A305) -> 0 | EJ13: =('Gestión de abastecimiento'!Q305) -> 0 | EK13: =('Gestión de abastecimiento'!Q311) -> 0 | ER13: =('Gestión de abastecimiento'!A305) -> 0 | ES13: =('Gestión de abastecimiento'!R305) -> 0 | ET13: =('Gestión de abastecimiento'!R311) -> 0 | FA13: =('Gestión de abastecimiento'!A305) -> 0 | FB13: =('Gestión de abastecimiento'!S305) -> 0 | FC13: =('Gestión de abastecimiento'!S311) -> 0
D14: Elaboración: Propia | M14: Elaboración: Propia | V14: Elaboración: Propia | AE14: Elaboración: Propia | AN14: Elaboración: Propia | AW14: Elaboración: Propia | BF14: Elaboración: Propia | BO14: Elaboración: Propia | BX14: Elaboración: Propia | CG14: Elaboración: Propia | CP14: Elaboración: Propia | CY14: Elaboración: Propia | DH14: Elaboración: Propia | DQ14: Elaboración: Propia | DZ14: Elaboración: Propia | EI14: Elaboración: Propia | ER14: Elaboración: Propia | FA14: Elaboración: Propia
D15: Fuente: Encuesta aplicada | M15: Fuente: Encuesta aplicada | V15: Fuente: Encuesta aplicada | AE15: Fuente: Encuesta aplicada | AN15: Fuente: Encuesta aplicada | AW15: Fuente: Encuesta aplicada | BF15: Fuente: Encuesta aplicada | BO15: Fuente: Encuesta aplicada | BX15: Fuente: Encuesta aplicada | CG15: Fuente: Encuesta aplicada | CP15: Fuente: Encuesta aplicada | CY15: Fuente: Encuesta aplicada | DH15: Fuente: Encuesta aplicada | DQ15: Fuente: Encuesta aplicada | DZ15: Fuente: Encuesta aplicada | EI15: Fuente: Encuesta aplicada | ER15: Fuente: Encuesta aplicada | FA15: Fuente: Encuesta aplicada
D33: Figura. 1 | M33: Figura. 2 | V33: Figura. 3 | AE33: Figura. 4 | AN33: Figura. 5 | AW33: Figura. 6 | BF33: Figura. 7 | BO33: Figura. 8 | BX33: Figura. 9 | CG33: Figura. 10 | CP33: Figura. 11 | CY33: Figura. 12 | DH33: Figura. 13 | DQ33: Figura. 14 | DZ33: Figura. 15 | EI33: Figura. 16 | ER33: Figura. 17 | FA33: Figura. 18
D34: x | M34: x | V34: x | AE34: x | AW34: x | BF34: x | BO34: x | BX34: x | CG34: x | CP34: x | CY34: x | DH34: x | DQ34: x | DZ34: x | EI34: x | ER34: x | FA34: x
